Workbook

Sheet A completar
A1: Variables | C1: Datos
A2: Nombre y Apellido
A3: Fecha
A4: Entrenamiento previo a la sesión
A5: Edad
A6: Altura en cm
A7: Peso en kg
A8: Pierna dominante
A9: Pierna lesionada
A10: Tipo de lesión
A11: Comentarios de la lesión | D11: Completar con: tipo de lesión, fecha de lesión, fecha de cirugía, tipo de injerto, lesión asociada, mecanismo de lesión
A12: Antecedentes
A13: Médico derivante
A14: Dolor durante la evaluación
A15: Rotación interna de cadera 90º | B15: Derecha
B16: Izquierda
A17: Rotación externa de cadera 90º | B17: Derecha
B18: Izquierda
A19: Extensión pasiva de rodilla | B19: Derecha
B20: Izquierda
A21: Flexión activa de rodilla | B21: Derecha
B22: Izquierda
A23: Flexión pasiva de rodilla | B23: Derecha
B24: Izquierda
A25: Flexión dorsal de tobillo | B25: Derecha
B26: Izquierda
A27: Rotación interna de hombro | B27: Derecho
B28: Izquierdo
A29: Rotación externa de hombro | B29: Derecho
B30: Izquierdo
A31: Perímetro de muslo | B31: Derecho
B32: Izquierdo
A33: Perímetro de pantorrilla | B33: Derecho
B34: Izquierdo
A35: Thomas derecha | B35: Psoas Iíaco
B36: Recto Anterior
B37: Sartorio
A38: Thomas izquierda | B38: Psoas Iíaco
B39: Recto Anterior
B40: Sartorio
...

Sheet Resultados
B8: PACIENTE | C8: ='A completar'!C2 | D8: FECHA | E8: ='A completar'!C3 | G8: ENTRENAMIENTO PREVIO A LA SESIÓN | I8: ='A completar'!C4
B9: EDAD | C9: ='A completar'!C5 | D9: ALTURA EN CM | E9: ='A completar'!C6 | G9: PESO EN KG | I9: ='A completar'!C7
B10: PIERNA DOMINANTE | C10: ='A completar'!C8 | D10: PIERNA LESIONADA | E10: ='A completar'!C9 | F10: TIPO DE LESIÓN | G10: ='A completar'!C10
B11: ='A completar'!C11
B12: ANTECEDENTES | C12: ='A completar'!C12
B13: MÉDICO DERIVANTE | C13: ='A completar'!C13 | E13: DOLOR DURANTE LA EVALUACIÓN | G13: No
B14: =IF(G13="No", "Todas las pruebas fueron realizadas sin dolor y a continuación se destacan los aspectos más relevantes.", "El paciente presentó dolor a lo largo de las evaluaciones y a continuación se destacan los aspectos más relevantes.") -> Todas las pruebas fueron realizadas sin dolor y a continuación se destacan los aspectos más relevantes.
B15: RANGO DE MOVILIDAD ARTICULAR - CADERA
B16: TEST - INSTRUMENTO | C16: MOVIMIENTO | D16: DERECHA | E16: IZQUIERDA | F16: REFERENCIA
B17: Rotación de cadera - Inclinómetro (º) | C17: Rotación interna (°) | D17: ='A completar'!C15 | E17: ='A completar'!C16 | F17: -
C18: Rotación externa (°) | D18: ='A completar'!C17 | E18: ='A completar'!C18 | F18: -
C19: Rotación total (°) | D19: =D17+D18 -> 0 | E19: =E17+E18 -> 0 | F19: 85º
B20: COMENTARIOS
B21: =IF(AND(D19>=85,E19>=85), "El rango de movimiento total de cadera en ambas piernas se encuentra normal.", IF(AND(D19<85,E19>=85), "El rango de movimiento total de cadera en la pierna derecha se encuentra disminuido.", IF(AND(D19>=85,E19<85), "El rango de movimiento total de cadera en la pierna izquierda se encuentra disminuido.", "El rango de movimiento total de cadera en ambas piernas se encuentra disminuido."))) -> El rango de movimiento total de cadera en ambas piernas se encuentra disminuido.
B22: RANGO DE MOVILIDAD ARTICULAR - RODILLA
B23: TEST - INSTRUMENTO | C23: MOVIMIENTO | D23: DERECHA | E23: IZQUIERDA | F23: REFERENCIA
B24: Extensión de rodilla - Inclinómetro (º) | C24: Exensión pasiva de rodilla | D24: ='A completar'!C19 | E24: ='A completar'!C20 | F24: 0º
B26: TEST - INSTRUMENTO | C26: MOVIMIENTO | D26: DERECHA | E26: IZQUIERDA | F26: DÉFICIT | G26: REFERENCIA
B27: Flexión rodilla - Inclinómetro (º) | C27: Flexión activa de rodilla | D27: ='A completar'!C21 | E27: ='A completar'!C22 | F27: =E27-D27 -> 0 | G27: 0º-10º
C28: Flexión pasiva de rodilla | D28: ='A completar'!C23 | E28: ='A completar'!C24 | F28: =E28-D28 -> 0 | G28: 0º-10º
B29: COMENTARIOS
B30: =IF(AND(D24=0,E24=0), "No presenta déficit de extensión.", "Se presenta déficit de extensión de la rodilla.") -> No presenta déficit de extensión.
B31: =IF(OR(F27<-10,F27>10), "Se presenta un déficit de flexión activa de la rodilla.", "La flexión activa de rodilla se encuentra normal.") -> La flexión activa de rodilla se encuentra normal.
B32: =IF(OR(F28<-10,F28>10), "Se presenta un déficit de flexión pasiva de la rodilla.", "La flexión pasiva de rodilla se encuentra normal.") -> La flexión pasiva de rodilla se encuentra normal.
B33: RANGO DE MOVILIDAD ARTICULAR - TOBILLO
B34: TEST - INSTRUMENTO | C34: MOVIMIENTO | D34: DERECHA | E34: IZQUIERDA | F34: REFERENCIA
B35: Lunge Test - Inclinómetro (º) | C35: Flexión dorsal de tobillo | D35: ='A completar'!C25 | E35: ='A completar'!C26 | F35: 39º
B36: COMENTARIOS
B37: =IF(AND(D35<39, E35<39), "Presenta un déficit de flexión dorsal del tobillo de ambas piernas.", IF(D35<39, "Presenta un déficit de flexión dorsal del tobillo de la pierna derecha.", IF(E35<39, "Presenta un déficit de flexión dorsal del tobillo de la pierna izquierda.", "No presenta déficit en la flexión dorsal del tobillo."))) -> Presenta un déficit de flexión dorsal del tobillo de ambas piernas.
B38: RANGO DE MOVILIDAD ARTICULAR - HOMBRO
B39: TEST - INSTRUMENTO | C39: MOVIMIENTO | D39: DERECHA | E39: IZQUIERDA | F39: DÉFICIT | G39: REFERENCIA
B40: Rotación de hombro - Inclinómetro (º) | C40: Rotación interna (°) | D40: ='A completar'!C27 | E40: ='A completar'!C28 | F40: =E40-D40 -> 0 | G40: 18º
C41: Rotación externa (°) | D41: ='A completar'!C29 | E41: ='A completar'!C30 | F41: =E41-D41 -> 0 | G41: -
C42: Rotación total (°) | D42: =D40+D41 -> 0 | E42: =E40+E41 -> 0 | F42: =E42-D42 -> 0 | G42: 5º
B43: COMENTARIOS
B44: =IF(OR(F40<-18,F40>18), "Se presenta un déficit de rotación interna del hombro.", "No se presenta un déficit de rotación interna del hombro.") -> No se presenta un déficit de rotación interna del hombro.
B45: =IF(AND(F42>=-5,F42<=5), "Se presenta un normal arco total del movimiento del hombro", "Se presenta un déficit del arco total del movimiento del hombro") -> Se presenta un normal arco total del movimiento del hombro
B46: PERÍMETROS MUSCULARES
B47: PERÍMETRO MUSCULAR | C47: DERECHA | D47: IZQUIERDA | E47: DÉFICIT
B48: Muslo | C48: ='A completar'!C31 | D48: ='A completar'!C32 | E48: =D48-C48 -> 0
...

Sheet Definición operativa
A1: 3 minutos en cinta caminata, rodilla al pecho en caminata, elongacion de cuadriceps en caminata, rodillas al pecho, talones a la cola, todos ida y vuelta del espacio verde
A2: Rotación interna de cadera 90º | B2: PASIVO.
A4: Rotación externa de cadera 90º
A6: Extensión pasiva de rodilla | B6: Inclinómetro (regla L), buscar superficie dura
A8: Flexión activa de rodilla | B8: Decúbito prono, inclinómetro en la tibia, sin entrada en calor
A10: Flexión pasiva de rodilla | B10: Decúbito prono, inclinómetro en la tibia, sin entrada en calor
A12: Flexión dorsal de tobillo | B12: Inclínometro borde anterior de tibia, moverlo 3 veces antes, no puede levantar talón, una sola medición, sin apoyar rodilla contraria en el suelo
A14: Rotación interna de hombro | B14: Fijación a la antepulsión con mano del evaluador, inclinómetro parte dorsal del antebrazo, decúbito supino completamente
A16: Rotación externa de hombro | B16: Fijación a la antepulsión con mano del evaluador, inclinómetro parte dorsal del antebrazo, decúbito supino completamente
A18: Peímetro de músculo y de gemelo | B18: Muslo medio: parado sobre banco, punto medio entre EIAS y borde superior de rótula
B19: Pantorilla: pierna sobre banco, medición de mayor pliegue ubicado de forma lateral
A20: Thomas derecha
A23: Thomas izquierda
A26: AKE
A28: Askling test
A30: Slump test
A32: BKFO test | B32: Decúbito supino, planta con planta, distancia de la cabeza de peroné a la camilla en cm
A34: Psoas derecha
A37: Psoas izquierda
A40: Pubis derecha
A43: Pubis izquierda
A46: Abdominales derecha
A49: Abdominales izquierda
A52: Aductor derecha
A55: Aductor izquierda
A58: Glúteo medio derecha
A59: Glúteo medio izquierda
A60: Cuadrado lumbar derecha
A61: Cuadrado lumbar izquierda
... A76: Y Balance izquierda
A79: Prueba de balance: derecha | B79: Los sujetos se colocan de pie sobre una sola pierna, con un leve grado de flexión en la cadera, la rodilla y el tobillo, y con las manos apoyadas en la cintura. A una frecuencia de 60 pulsaciones por minuto, los sujetos giran repetidamente la cabeza de un lado al otro (entre 70 y 90 grados) durante un período de 15 segundos. La visión debe estar alineada con la posición de la cabeza (sin fijación visual).
A81: Prueba de balance: izquierda
A83: Prueba de balance vestibular: derecha | B83: Los sujetos se colocan de pie sobre una sola pierna, con un leve grado de flexión en la cadera, la rodilla y el tobillo, y con las manos apoyadas en la cintura. A una frecuencia de 60 pulsaciones por minuto, los sujetos inclinan repetidamente la cabeza hacia arriba y hacia abajo (mirando del piso al techo) durante un período de 15 segundos. La visión debe estar alineada con la posición de la cabeza (sin fijación visual). La prueba se considera aprobada si los sujetos pueden mantener la postura en apoyo unipodal y no retiran las manos de la cintura en ambas evaluaciones.
A85: Prueba de balance vestibular: izquierda
A87: Mc Gill | B87: con valla abajo del cuerpo, flexores a 45°, si toca atrás corta, o si toca la valla de costado
A89: Mc Gill
A91: Puente glúteo a 1p | B91: Cajón de 60 cm, flexión de rodilla de 20º, brazos en pecho, apoyo de talón, llevar a extensión de cadera de 0º
A93: Puente glúteo a 1p VAS
A95: Elevación gemelo a 1p | B95: Sobre pesa de 15kg, cabeza metatarsianos
A97: Elevación gemelo a 1p VAS
...
